<?xml version="1.0" ?>
<!-- =================================================================================== -->
<!-- |    This document was autogenerated by xacro from robot.urdf.xacro               | -->
<!-- |    EDITING THIS FILE BY HAND IS NOT RECOMMENDED                                 | -->
<!-- =================================================================================== -->
<robot name="myRobot">
  <!-- ##################################################################################### -->
  <!-- Links -->
  <link name="world"/>
  <link name="base_link">
    <visual>
      <origin rpy="0.0 0.0 0.0" xyz="-0.5 -0.5 0.0"/>
      <geometry>
        <mesh filename="package://arduinobot_description/meshes/basement.STL" scale="0.01 0.01 0.01"/>
      </geometry>
    </visual>
  </link>
  <link name="base_plate">
    <visual>
      <origin rpy="0.0 0.0 0.0" xyz="-0.39 -0.39 -0.56"/>
      <geometry>
        <mesh filename="package://arduinobot_description/meshes/base_plate.STL" scale="0.01 0.01 0.01"/>
      </geometry>
    </visual>
  </link>
  <link name="forward_drive_arm">
    <visual>
      <origin rpy="0.0 -1.5707963267948966 1.5707963267948966" xyz="0.19 0.06 -0.08"/>
      <geometry>
        <mesh filename="package://arduinobot_description/meshes/forward_drive_arm.STL" scale="0.01 0.01 0.01"/>
      </geometry>
    </visual>
  </link>
  <link name="horizontal_arm">
    <visual>
      <origin rpy="1.5707963267948966 0 1.5707963267948966" xyz="-0.03 -0.4 -0.06"/>
      <geometry>
        <mesh filename="package://arduinobot_description/meshes/horizontal_arm.STL" scale="0.01 0.01 0.01"/>
      </geometry>
    </visual>
  </link>
  <link name="claw_support">
    <visual>
      <origin rpy="0.0 0.0 1.5707963267948966" xyz="0.0 -0.05 -0.15"/>
      <geometry>
        <mesh filename="package://arduinobot_description/meshes/claw_support.STL" scale="0.01 0.01 0.01"/>
      </geometry>
    </visual>
  </link>
  <link name="gripper_right">
    <visual>
      <origin rpy="0 0 -1.5707963267948966" xyz="-0.1 0.5 -0.1"/>
      <geometry>
        <mesh filename="package://arduinobot_description/meshes/right_finger.STL" scale="0.01 0.01 0.01"/>
      </geometry>
    </visual>
  </link>
  <link name="gripper_left">
    <visual>
      <origin rpy="0.0 0.0 -1.5707963267948966" xyz="-0.04 0.5 -0.1"/>
      <geometry>
        <mesh filename="package://arduinobot_description/meshes/left_finger.STL" scale="0.01 0.01 0.01"/>
      </geometry>
    </visual>
  </link>
  <!-- ##################################################################################### -->
  <!-- Joints -->
  <joint name="virtual_joint" type="fixed">
    <parent link="world"/>
    <child link="base_link"/>
    <origin rpy="0.0 0.0 0.0" xyz="0.0 0.0 0.0"/>
  </joint>
  <joint name="joint_1" type="revolute">
    <parent link="base_link"/>
    <child link="base_plate"/>
    <axis xyz="0.0 0.0 1"/>
    <origin rpy="0.0 0.0 0.0" xyz="0.0 0.0 0.307"/>
    <limit effort="30.0" lower="-1.5707963267948966" upper="1.5707963267948966" velocity="10.0"/>
  </joint>
  <joint name="joint_2" type="revolute">
    <parent link="base_plate"/>
    <child link="forward_drive_arm"/>
    <axis xyz="1 0.0 0.0"/>
    <origin rpy="0.0 0.0 0.0" xyz="-0.02 0.0 0.35"/>
    <limit effort="30.0" lower="-1.5707963267948966" upper="1.5707963267948966" velocity="10.0"/>
  </joint>
  <joint name="joint_3" type="revolute">
    <parent link="forward_drive_arm"/>
    <child link="horizontal_arm"/>
    <axis xyz="1 0.0 0.0"/>
    <origin rpy="0.0 0.0 0.0" xyz="0.0 0.0 0.8"/>
    <limit effort="30.0" lower="-1.5707963267948966" upper="1.5707963267948966" velocity="10.0"/>
  </joint>
  <joint name="horizontal_arm_to_claw_support" type="fixed">
    <parent link="horizontal_arm"/>
    <child link="claw_support"/>
    <origin rpy="0.0 0.0 0.0" xyz="0.0 0.82 0.0"/>
  </joint>
  <joint name="joint_4" type="revolute">
    <parent link="claw_support"/>
    <child link="gripper_right"/>
    <axis xyz="0.0 0.0 1"/>
    <origin rpy="0.0 0.0 0.0" xyz="-0.04 0.13 -0.1"/>
    <limit effort="30.0" lower="-1.5707963267948966" upper="0.0" velocity="10.0"/>
  </joint>
  <joint name="joint_5" type="revolute">
    <parent link="claw_support"/>
    <child link="gripper_left"/>
    <axis xyz="0.0 0.0 1"/>
    <origin rpy="0.0 0.0 0.0" xyz="-0.22 0.13 -0.1"/>
    <mimic joint="joint_4" multiplier="-1"/>
    <limit effort="30.0" lower="0.0" upper="1.5707963267948966" velocity="10.0"/>
  </joint>
</robot>
